{
 "cells": [
  {
   "cell_type": "code",
   "execution_count": 1,
   "id": "58e1110d",
   "metadata": {},
   "outputs": [],
   "source": [
    "import numpy as np\n",
    "import tensorflow as tf\n",
    "import tensorflow_datasets as tfds"
   ]
  },
  {
   "cell_type": "code",
   "execution_count": null,
   "id": "a348fe21",
   "metadata": {},
   "outputs": [
    {
     "name": "stdout",
     "output_type": "stream",
     "text": [
      "\u001b[1mDownloading and preparing dataset mnist (11.06 MiB) to /Users/hiradekeishi/tensorflow_datasets/mnist/1.0.0...\u001b[0m\n"
     ]
    },
    {
     "name": "stderr",
     "output_type": "stream",
     "text": [
      "ERROR:root:Internal Python error in the inspect module.\n",
      "Below is the traceback from this internal error.\n",
      "\n",
      "ERROR:root:Internal Python error in the inspect module.\n",
      "Below is the traceback from this internal error.\n",
      "\n",
      "ERROR:root:Internal Python error in the inspect module.\n",
      "Below is the traceback from this internal error.\n",
      "\n"
     ]
    },
    {
     "name": "stdout",
     "output_type": "stream",
     "text": [
      "Traceback (most recent call last):\n",
      "  File \"/Users/hiradekeishi/opt/anaconda3/envs/py3-TF2.0/lib/python3.7/site-packages/IPython/core/interactiveshell.py\", line 3457, in run_code\n",
      "    exec(code_obj, self.user_global_ns, self.user_ns)\n",
      "  File \"/var/folders/7_/5ly65s3j46zcgtgg9r0sjm940000gn/T/ipykernel_84481/3073791597.py\", line 1, in <module>\n",
      "    mnist_dataset, mnist_info = tfds.load(name='mnist', with_info=True, as_supervised=True)\n",
      "  File \"/Users/hiradekeishi/Desktop/k-hirade_private/deep_learning/cakephp/Mnist/tensorflow_datasets/core/api_utils.py\", line 52, in disallow_positional_args_dec\n",
      "    return fn(*args, **kwargs)\n",
      "  File \"/Users/hiradekeishi/Desktop/k-hirade_private/deep_learning/cakephp/Mnist/tensorflow_datasets/core/registered.py\", line 300, in load\n",
      "    dbuilder.download_and_prepare(**download_and_prepare_kwargs)\n",
      "  File \"/Users/hiradekeishi/Desktop/k-hirade_private/deep_learning/cakephp/Mnist/tensorflow_datasets/core/api_utils.py\", line 52, in disallow_positional_args_dec\n",
      "    return fn(*args, **kwargs)\n",
      "  File \"/Users/hiradekeishi/Desktop/k-hirade_private/deep_learning/cakephp/Mnist/tensorflow_datasets/core/dataset_builder.py\", line 287, in download_and_prepare\n",
      "    download_config=download_config)\n",
      "  File \"/Users/hiradekeishi/Desktop/k-hirade_private/deep_learning/cakephp/Mnist/tensorflow_datasets/core/dataset_builder.py\", line 948, in _download_and_prepare\n",
      "    max_examples_per_split=download_config.max_examples_per_split,\n",
      "  File \"/Users/hiradekeishi/Desktop/k-hirade_private/deep_learning/cakephp/Mnist/tensorflow_datasets/core/dataset_builder.py\", line 804, in _download_and_prepare\n",
      "    for split_generator in self._split_generators(dl_manager):\n",
      "  File \"/Users/hiradekeishi/Desktop/k-hirade_private/deep_learning/cakephp/Mnist/tensorflow_datasets/image/mnist.py\", line 132, in _split_generators\n",
      "    {k: urllib.parse.urljoin(self.URL, v) for k, v in filenames.items()})\n",
      "  File \"/Users/hiradekeishi/Desktop/k-hirade_private/deep_learning/cakephp/Mnist/tensorflow_datasets/core/download/download_manager.py\", line 357, in download_and_extract\n",
      "    with self._downloader.tqdm():\n",
      "  File \"/Users/hiradekeishi/opt/anaconda3/envs/py3-TF2.0/lib/python3.7/contextlib.py\", line 112, in __enter__\n",
      "    return next(self.gen)\n",
      "  File \"/Users/hiradekeishi/Desktop/k-hirade_private/deep_learning/cakephp/Mnist/tensorflow_datasets/core/download/downloader.py\", line 89, in tqdm\n",
      "    with async_tqdm(total=0, desc='Dl Completed...', unit=' url') as pbar_url:\n",
      "  File \"/Users/hiradekeishi/opt/anaconda3/envs/py3-TF2.0/lib/python3.7/contextlib.py\", line 112, in __enter__\n",
      "    return next(self.gen)\n",
      "  File \"/Users/hiradekeishi/Desktop/k-hirade_private/deep_learning/cakephp/Mnist/tensorflow_datasets/core/utils/tqdm_utils.py\", line 98, in _async_tqdm\n",
      "    with tqdm_lib.tqdm(*args, **kwargs) as pbar:\n",
      "  File \"/Users/hiradekeishi/opt/anaconda3/envs/py3-TF2.0/lib/python3.7/site-packages/tqdm/notebook.py\", line 242, in __init__\n",
      "    self.container = self.status_printer(self.fp, total, self.desc, self.ncols)\n",
      "  File \"/Users/hiradekeishi/opt/anaconda3/envs/py3-TF2.0/lib/python3.7/site-packages/tqdm/notebook.py\", line 116, in status_printer\n",
      "    \"IProgress not found. Please update jupyter and ipywidgets.\"\n",
      "ImportError: IProgress not found. Please update jupyter and ipywidgets. See https://ipywidgets.readthedocs.io/en/stable/user_install.html\n",
      "\n",
      "During handling of the above exception, another exception occurred:\n",
      "\n",
      "Traceback (most recent call last):\n",
      "  File \"/Users/hiradekeishi/opt/anaconda3/envs/py3-TF2.0/lib/python3.7/site-packages/IPython/core/interactiveshell.py\", line 2077, in showtraceback\n",
      "    stb = value._render_traceback_()\n",
      "AttributeError: 'ImportError' object has no attribute '_render_traceback_'\n",
      "\n",
      "During handling of the above exception, another exception occurred:\n",
      "\n",
      "Traceback (most recent call last):\n",
      "  File \"/Users/hiradekeishi/opt/anaconda3/envs/py3-TF2.0/lib/python3.7/site-packages/IPython/core/ultratb.py\", line 1101, in get_records\n",
      "    return _fixed_getinnerframes(etb, number_of_lines_of_context, tb_offset)\n",
      "  File \"/Users/hiradekeishi/opt/anaconda3/envs/py3-TF2.0/lib/python3.7/site-packages/IPython/core/ultratb.py\", line 248, in wrapped\n",
      "    return f(*args, **kwargs)\n",
      "  File \"/Users/hiradekeishi/opt/anaconda3/envs/py3-TF2.0/lib/python3.7/site-packages/IPython/core/ultratb.py\", line 281, in _fixed_getinnerframes\n",
      "    records = fix_frame_records_filenames(inspect.getinnerframes(etb, context))\n",
      "  File \"/Users/hiradekeishi/opt/anaconda3/envs/py3-TF2.0/lib/python3.7/inspect.py\", line 1502, in getinnerframes\n",
      "    frameinfo = (tb.tb_frame,) + getframeinfo(tb, context)\n",
      "  File \"/Users/hiradekeishi/opt/anaconda3/envs/py3-TF2.0/lib/python3.7/inspect.py\", line 1460, in getframeinfo\n",
      "    filename = getsourcefile(frame) or getfile(frame)\n",
      "  File \"/Users/hiradekeishi/opt/anaconda3/envs/py3-TF2.0/lib/python3.7/inspect.py\", line 696, in getsourcefile\n",
      "    if getattr(getmodule(object, filename), '__loader__', None) is not None:\n",
      "  File \"/Users/hiradekeishi/opt/anaconda3/envs/py3-TF2.0/lib/python3.7/inspect.py\", line 733, in getmodule\n",
      "    if ismodule(module) and hasattr(module, '__file__'):\n",
      "  File \"/Users/hiradekeishi/opt/anaconda3/envs/py3-TF2.0/lib/python3.7/site-packages/tensorflow/__init__.py\", line 50, in __getattr__\n",
      "    module = self._load()\n",
      "  File \"/Users/hiradekeishi/opt/anaconda3/envs/py3-TF2.0/lib/python3.7/site-packages/tensorflow/__init__.py\", line 44, in _load\n",
      "    module = _importlib.import_module(self.__name__)\n",
      "  File \"/Users/hiradekeishi/opt/anaconda3/envs/py3-TF2.0/lib/python3.7/importlib/__init__.py\", line 127, in import_module\n",
      "    return _bootstrap._gcd_import(name[level:], package, level)\n",
      "  File \"<frozen importlib._bootstrap>\", line 1006, in _gcd_import\n",
      "  File \"<frozen importlib._bootstrap>\", line 983, in _find_and_load\n",
      "  File \"<frozen importlib._bootstrap>\", line 965, in _find_and_load_unlocked\n",
      "ModuleNotFoundError: No module named 'tensorflow_core.estimator'\n",
      "Traceback (most recent call last):\n",
      "  File \"/Users/hiradekeishi/opt/anaconda3/envs/py3-TF2.0/lib/python3.7/site-packages/IPython/core/interactiveshell.py\", line 3457, in run_code\n",
      "    exec(code_obj, self.user_global_ns, self.user_ns)\n",
      "  File \"/var/folders/7_/5ly65s3j46zcgtgg9r0sjm940000gn/T/ipykernel_84481/3073791597.py\", line 1, in <module>\n",
      "    mnist_dataset, mnist_info = tfds.load(name='mnist', with_info=True, as_supervised=True)\n",
      "  File \"/Users/hiradekeishi/Desktop/k-hirade_private/deep_learning/cakephp/Mnist/tensorflow_datasets/core/api_utils.py\", line 52, in disallow_positional_args_dec\n",
      "    return fn(*args, **kwargs)\n",
      "  File \"/Users/hiradekeishi/Desktop/k-hirade_private/deep_learning/cakephp/Mnist/tensorflow_datasets/core/registered.py\", line 300, in load\n",
      "    dbuilder.download_and_prepare(**download_and_prepare_kwargs)\n",
      "  File \"/Users/hiradekeishi/Desktop/k-hirade_private/deep_learning/cakephp/Mnist/tensorflow_datasets/core/api_utils.py\", line 52, in disallow_positional_args_dec\n",
      "    return fn(*args, **kwargs)\n",
      "  File \"/Users/hiradekeishi/Desktop/k-hirade_private/deep_learning/cakephp/Mnist/tensorflow_datasets/core/dataset_builder.py\", line 287, in download_and_prepare\n",
      "    download_config=download_config)\n",
      "  File \"/Users/hiradekeishi/Desktop/k-hirade_private/deep_learning/cakephp/Mnist/tensorflow_datasets/core/dataset_builder.py\", line 948, in _download_and_prepare\n",
      "    max_examples_per_split=download_config.max_examples_per_split,\n",
      "  File \"/Users/hiradekeishi/Desktop/k-hirade_private/deep_learning/cakephp/Mnist/tensorflow_datasets/core/dataset_builder.py\", line 804, in _download_and_prepare\n",
      "    for split_generator in self._split_generators(dl_manager):\n",
      "  File \"/Users/hiradekeishi/Desktop/k-hirade_private/deep_learning/cakephp/Mnist/tensorflow_datasets/image/mnist.py\", line 132, in _split_generators\n",
      "    {k: urllib.parse.urljoin(self.URL, v) for k, v in filenames.items()})\n",
      "  File \"/Users/hiradekeishi/Desktop/k-hirade_private/deep_learning/cakephp/Mnist/tensorflow_datasets/core/download/download_manager.py\", line 357, in download_and_extract\n",
      "    with self._downloader.tqdm():\n",
      "  File \"/Users/hiradekeishi/opt/anaconda3/envs/py3-TF2.0/lib/python3.7/contextlib.py\", line 112, in __enter__\n",
      "    return next(self.gen)\n",
      "  File \"/Users/hiradekeishi/Desktop/k-hirade_private/deep_learning/cakephp/Mnist/tensorflow_datasets/core/download/downloader.py\", line 89, in tqdm\n",
      "    with async_tqdm(total=0, desc='Dl Completed...', unit=' url') as pbar_url:\n",
      "  File \"/Users/hiradekeishi/opt/anaconda3/envs/py3-TF2.0/lib/python3.7/contextlib.py\", line 112, in __enter__\n",
      "    return next(self.gen)\n",
      "  File \"/Users/hiradekeishi/Desktop/k-hirade_private/deep_learning/cakephp/Mnist/tensorflow_datasets/core/utils/tqdm_utils.py\", line 98, in _async_tqdm\n",
      "    with tqdm_lib.tqdm(*args, **kwargs) as pbar:\n",
      "  File \"/Users/hiradekeishi/opt/anaconda3/envs/py3-TF2.0/lib/python3.7/site-packages/tqdm/notebook.py\", line 242, in __init__\n",
      "    self.container = self.status_printer(self.fp, total, self.desc, self.ncols)\n",
      "  File \"/Users/hiradekeishi/opt/anaconda3/envs/py3-TF2.0/lib/python3.7/site-packages/tqdm/notebook.py\", line 116, in status_printer\n",
      "    \"IProgress not found. Please update jupyter and ipywidgets.\"\n",
      "ImportError: IProgress not found. Please update jupyter and ipywidgets. See https://ipywidgets.readthedocs.io/en/stable/user_install.html\n",
      "\n",
      "During handling of the above exception, another exception occurred:\n",
      "\n",
      "Traceback (most recent call last):\n",
      "  File \"/Users/hiradekeishi/opt/anaconda3/envs/py3-TF2.0/lib/python3.7/site-packages/IPython/core/interactiveshell.py\", line 2077, in showtraceback\n",
      "    stb = value._render_traceback_()\n",
      "AttributeError: 'ImportError' object has no attribute '_render_traceback_'\n",
      "\n",
      "During handling of the above exception, another exception occurred:\n",
      "\n",
      "Traceback (most recent call last):\n",
      "  File \"/Users/hiradekeishi/opt/anaconda3/envs/py3-TF2.0/lib/python3.7/site-packages/IPython/core/interactiveshell.py\", line 3377, in run_ast_nodes\n",
      "    if (await self.run_code(code, result,  async_=asy)):\n",
      "  File \"/Users/hiradekeishi/opt/anaconda3/envs/py3-TF2.0/lib/python3.7/site-packages/IPython/core/interactiveshell.py\", line 3474, in run_code\n",
      "    self.showtraceback(running_compiled_code=True)\n",
      "  File \"/Users/hiradekeishi/opt/anaconda3/envs/py3-TF2.0/lib/python3.7/site-packages/IPython/core/interactiveshell.py\", line 2080, in showtraceback\n",
      "    value, tb, tb_offset=tb_offset)\n",
      "  File \"/Users/hiradekeishi/opt/anaconda3/envs/py3-TF2.0/lib/python3.7/site-packages/IPython/core/ultratb.py\", line 1368, in structured_traceback\n",
      "    self, etype, value, tb, tb_offset, number_of_lines_of_context)\n",
      "  File \"/Users/hiradekeishi/opt/anaconda3/envs/py3-TF2.0/lib/python3.7/site-packages/IPython/core/ultratb.py\", line 1268, in structured_traceback\n",
      "    self, etype, value, tb, tb_offset, number_of_lines_of_context\n",
      "  File \"/Users/hiradekeishi/opt/anaconda3/envs/py3-TF2.0/lib/python3.7/site-packages/IPython/core/ultratb.py\", line 1125, in structured_traceback\n",
      "    tb_offset)\n",
      "  File \"/Users/hiradekeishi/opt/anaconda3/envs/py3-TF2.0/lib/python3.7/site-packages/IPython/core/ultratb.py\", line 1082, in format_exception_as_a_whole\n",
      "    last_unique, recursion_repeat = find_recursion(orig_etype, evalue, records)\n",
      "  File \"/Users/hiradekeishi/opt/anaconda3/envs/py3-TF2.0/lib/python3.7/site-packages/IPython/core/ultratb.py\", line 382, in find_recursion\n",
      "    return len(records), 0\n",
      "TypeError: object of type 'NoneType' has no len()\n",
      "\n",
      "During handling of the above exception, another exception occurred:\n",
      "\n",
      "Traceback (most recent call last):\n",
      "  File \"/Users/hiradekeishi/opt/anaconda3/envs/py3-TF2.0/lib/python3.7/site-packages/IPython/core/interactiveshell.py\", line 2077, in showtraceback\n",
      "    stb = value._render_traceback_()\n",
      "AttributeError: 'TypeError' object has no attribute '_render_traceback_'\n",
      "\n",
      "During handling of the above exception, another exception occurred:\n",
      "\n",
      "Traceback (most recent call last):\n",
      "  File \"/Users/hiradekeishi/opt/anaconda3/envs/py3-TF2.0/lib/python3.7/site-packages/IPython/core/ultratb.py\", line 1101, in get_records\n",
      "    return _fixed_getinnerframes(etb, number_of_lines_of_context, tb_offset)\n",
      "  File \"/Users/hiradekeishi/opt/anaconda3/envs/py3-TF2.0/lib/python3.7/site-packages/IPython/core/ultratb.py\", line 248, in wrapped\n",
      "    return f(*args, **kwargs)\n",
      "  File \"/Users/hiradekeishi/opt/anaconda3/envs/py3-TF2.0/lib/python3.7/site-packages/IPython/core/ultratb.py\", line 281, in _fixed_getinnerframes\n",
      "    records = fix_frame_records_filenames(inspect.getinnerframes(etb, context))\n",
      "  File \"/Users/hiradekeishi/opt/anaconda3/envs/py3-TF2.0/lib/python3.7/inspect.py\", line 1502, in getinnerframes\n",
      "    frameinfo = (tb.tb_frame,) + getframeinfo(tb, context)\n",
      "  File \"/Users/hiradekeishi/opt/anaconda3/envs/py3-TF2.0/lib/python3.7/inspect.py\", line 1460, in getframeinfo\n",
      "    filename = getsourcefile(frame) or getfile(frame)\n",
      "  File \"/Users/hiradekeishi/opt/anaconda3/envs/py3-TF2.0/lib/python3.7/inspect.py\", line 696, in getsourcefile\n",
      "    if getattr(getmodule(object, filename), '__loader__', None) is not None:\n",
      "  File \"/Users/hiradekeishi/opt/anaconda3/envs/py3-TF2.0/lib/python3.7/inspect.py\", line 733, in getmodule\n",
      "    if ismodule(module) and hasattr(module, '__file__'):\n",
      "  File \"/Users/hiradekeishi/opt/anaconda3/envs/py3-TF2.0/lib/python3.7/site-packages/tensorflow/__init__.py\", line 50, in __getattr__\n",
      "    module = self._load()\n",
      "  File \"/Users/hiradekeishi/opt/anaconda3/envs/py3-TF2.0/lib/python3.7/site-packages/tensorflow/__init__.py\", line 44, in _load\n",
      "    module = _importlib.import_module(self.__name__)\n",
      "  File \"/Users/hiradekeishi/opt/anaconda3/envs/py3-TF2.0/lib/python3.7/importlib/__init__.py\", line 127, in import_module\n",
      "    return _bootstrap._gcd_import(name[level:], package, level)\n",
      "  File \"<frozen importlib._bootstrap>\", line 1006, in _gcd_import\n",
      "  File \"<frozen importlib._bootstrap>\", line 983, in _find_and_load\n",
      "  File \"<frozen importlib._bootstrap>\", line 965, in _find_and_load_unlocked\n",
      "ModuleNotFoundError: No module named 'tensorflow_core.estimator'\n",
      "Traceback (most recent call last):\n",
      "  File \"/Users/hiradekeishi/opt/anaconda3/envs/py3-TF2.0/lib/python3.7/site-packages/IPython/core/interactiveshell.py\", line 3457, in run_code\n",
      "    exec(code_obj, self.user_global_ns, self.user_ns)\n",
      "  File \"/var/folders/7_/5ly65s3j46zcgtgg9r0sjm940000gn/T/ipykernel_84481/3073791597.py\", line 1, in <module>\n",
      "    mnist_dataset, mnist_info = tfds.load(name='mnist', with_info=True, as_supervised=True)\n",
      "  File \"/Users/hiradekeishi/Desktop/k-hirade_private/deep_learning/cakephp/Mnist/tensorflow_datasets/core/api_utils.py\", line 52, in disallow_positional_args_dec\n",
      "    return fn(*args, **kwargs)\n",
      "  File \"/Users/hiradekeishi/Desktop/k-hirade_private/deep_learning/cakephp/Mnist/tensorflow_datasets/core/registered.py\", line 300, in load\n",
      "    dbuilder.download_and_prepare(**download_and_prepare_kwargs)\n",
      "  File \"/Users/hiradekeishi/Desktop/k-hirade_private/deep_learning/cakephp/Mnist/tensorflow_datasets/core/api_utils.py\", line 52, in disallow_positional_args_dec\n",
      "    return fn(*args, **kwargs)\n",
      "  File \"/Users/hiradekeishi/Desktop/k-hirade_private/deep_learning/cakephp/Mnist/tensorflow_datasets/core/dataset_builder.py\", line 287, in download_and_prepare\n",
      "    download_config=download_config)\n",
      "  File \"/Users/hiradekeishi/Desktop/k-hirade_private/deep_learning/cakephp/Mnist/tensorflow_datasets/core/dataset_builder.py\", line 948, in _download_and_prepare\n",
      "    max_examples_per_split=download_config.max_examples_per_split,\n",
      "  File \"/Users/hiradekeishi/Desktop/k-hirade_private/deep_learning/cakephp/Mnist/tensorflow_datasets/core/dataset_builder.py\", line 804, in _download_and_prepare\n",
      "    for split_generator in self._split_generators(dl_manager):\n",
      "  File \"/Users/hiradekeishi/Desktop/k-hirade_private/deep_learning/cakephp/Mnist/tensorflow_datasets/image/mnist.py\", line 132, in _split_generators\n",
      "    {k: urllib.parse.urljoin(self.URL, v) for k, v in filenames.items()})\n",
      "  File \"/Users/hiradekeishi/Desktop/k-hirade_private/deep_learning/cakephp/Mnist/tensorflow_datasets/core/download/download_manager.py\", line 357, in download_and_extract\n",
      "    with self._downloader.tqdm():\n",
      "  File \"/Users/hiradekeishi/opt/anaconda3/envs/py3-TF2.0/lib/python3.7/contextlib.py\", line 112, in __enter__\n",
      "    return next(self.gen)\n",
      "  File \"/Users/hiradekeishi/Desktop/k-hirade_private/deep_learning/cakephp/Mnist/tensorflow_datasets/core/download/downloader.py\", line 89, in tqdm\n",
      "    with async_tqdm(total=0, desc='Dl Completed...', unit=' url') as pbar_url:\n",
      "  File \"/Users/hiradekeishi/opt/anaconda3/envs/py3-TF2.0/lib/python3.7/contextlib.py\", line 112, in __enter__\n",
      "    return next(self.gen)\n",
      "  File \"/Users/hiradekeishi/Desktop/k-hirade_private/deep_learning/cakephp/Mnist/tensorflow_datasets/core/utils/tqdm_utils.py\", line 98, in _async_tqdm\n",
      "    with tqdm_lib.tqdm(*args, **kwargs) as pbar:\n",
      "  File \"/Users/hiradekeishi/opt/anaconda3/envs/py3-TF2.0/lib/python3.7/site-packages/tqdm/notebook.py\", line 242, in __init__\n",
      "    self.container = self.status_printer(self.fp, total, self.desc, self.ncols)\n",
      "  File \"/Users/hiradekeishi/opt/anaconda3/envs/py3-TF2.0/lib/python3.7/site-packages/tqdm/notebook.py\", line 116, in status_printer\n",
      "    \"IProgress not found. Please update jupyter and ipywidgets.\"\n",
      "ImportError: IProgress not found. Please update jupyter and ipywidgets. See https://ipywidgets.readthedocs.io/en/stable/user_install.html\n",
      "\n",
      "During handling of the above exception, another exception occurred:\n",
      "\n",
      "Traceback (most recent call last):\n",
      "  File \"/Users/hiradekeishi/opt/anaconda3/envs/py3-TF2.0/lib/python3.7/site-packages/IPython/core/interactiveshell.py\", line 2077, in showtraceback\n",
      "    stb = value._render_traceback_()\n",
      "AttributeError: 'ImportError' object has no attribute '_render_traceback_'\n",
      "\n",
      "During handling of the above exception, another exception occurred:\n",
      "\n",
      "Traceback (most recent call last):\n",
      "  File \"/Users/hiradekeishi/opt/anaconda3/envs/py3-TF2.0/lib/python3.7/site-packages/IPython/core/interactiveshell.py\", line 3377, in run_ast_nodes\n",
      "    if (await self.run_code(code, result,  async_=asy)):\n",
      "  File \"/Users/hiradekeishi/opt/anaconda3/envs/py3-TF2.0/lib/python3.7/site-packages/IPython/core/interactiveshell.py\", line 3474, in run_code\n",
      "    self.showtraceback(running_compiled_code=True)\n",
      "  File \"/Users/hiradekeishi/opt/anaconda3/envs/py3-TF2.0/lib/python3.7/site-packages/IPython/core/interactiveshell.py\", line 2080, in showtraceback\n",
      "    value, tb, tb_offset=tb_offset)\n",
      "  File \"/Users/hiradekeishi/opt/anaconda3/envs/py3-TF2.0/lib/python3.7/site-packages/IPython/core/ultratb.py\", line 1368, in structured_traceback\n",
      "    self, etype, value, tb, tb_offset, number_of_lines_of_context)\n",
      "  File \"/Users/hiradekeishi/opt/anaconda3/envs/py3-TF2.0/lib/python3.7/site-packages/IPython/core/ultratb.py\", line 1268, in structured_traceback\n",
      "    self, etype, value, tb, tb_offset, number_of_lines_of_context\n",
      "  File \"/Users/hiradekeishi/opt/anaconda3/envs/py3-TF2.0/lib/python3.7/site-packages/IPython/core/ultratb.py\", line 1125, in structured_traceback\n",
      "    tb_offset)\n",
      "  File \"/Users/hiradekeishi/opt/anaconda3/envs/py3-TF2.0/lib/python3.7/site-packages/IPython/core/ultratb.py\", line 1082, in format_exception_as_a_whole\n",
      "    last_unique, recursion_repeat = find_recursion(orig_etype, evalue, records)\n",
      "  File \"/Users/hiradekeishi/opt/anaconda3/envs/py3-TF2.0/lib/python3.7/site-packages/IPython/core/ultratb.py\", line 382, in find_recursion\n",
      "    return len(records), 0\n",
      "TypeError: object of type 'NoneType' has no len()\n",
      "\n",
      "During handling of the above exception, another exception occurred:\n",
      "\n",
      "Traceback (most recent call last):\n",
      "  File \"/Users/hiradekeishi/opt/anaconda3/envs/py3-TF2.0/lib/python3.7/site-packages/IPython/core/interactiveshell.py\", line 2077, in showtraceback\n",
      "    stb = value._render_traceback_()\n",
      "AttributeError: 'TypeError' object has no attribute '_render_traceback_'\n",
      "\n",
      "During handling of the above exception, another exception occurred:\n",
      "\n",
      "Traceback (most recent call last):\n",
      "  File \"/Users/hiradekeishi/opt/anaconda3/envs/py3-TF2.0/lib/python3.7/site-packages/IPython/core/interactiveshell.py\", line 2960, in _run_cell\n",
      "    return runner(coro)\n",
      "  File \"/Users/hiradekeishi/opt/anaconda3/envs/py3-TF2.0/lib/python3.7/site-packages/IPython/core/async_helpers.py\", line 78, in _pseudo_sync_runner\n",
      "    coro.send(None)\n",
      "  File \"/Users/hiradekeishi/opt/anaconda3/envs/py3-TF2.0/lib/python3.7/site-packages/IPython/core/interactiveshell.py\", line 3186, in run_cell_async\n",
      "    interactivity=interactivity, compiler=compiler, result=result)\n",
      "  File \"/Users/hiradekeishi/opt/anaconda3/envs/py3-TF2.0/lib/python3.7/site-packages/IPython/core/interactiveshell.py\", line 3396, in run_ast_nodes\n",
      "    self.showtraceback()\n",
      "  File \"/Users/hiradekeishi/opt/anaconda3/envs/py3-TF2.0/lib/python3.7/site-packages/IPython/core/interactiveshell.py\", line 2080, in showtraceback\n",
      "    value, tb, tb_offset=tb_offset)\n",
      "  File \"/Users/hiradekeishi/opt/anaconda3/envs/py3-TF2.0/lib/python3.7/site-packages/IPython/core/ultratb.py\", line 1368, in structured_traceback\n",
      "    self, etype, value, tb, tb_offset, number_of_lines_of_context)\n",
      "  File \"/Users/hiradekeishi/opt/anaconda3/envs/py3-TF2.0/lib/python3.7/site-packages/IPython/core/ultratb.py\", line 1268, in structured_traceback\n",
      "    self, etype, value, tb, tb_offset, number_of_lines_of_context\n",
      "  File \"/Users/hiradekeishi/opt/anaconda3/envs/py3-TF2.0/lib/python3.7/site-packages/IPython/core/ultratb.py\", line 1143, in structured_traceback\n",
      "    chained_exceptions_tb_offset)\n",
      "  File \"/Users/hiradekeishi/opt/anaconda3/envs/py3-TF2.0/lib/python3.7/site-packages/IPython/core/ultratb.py\", line 1082, in format_exception_as_a_whole\n",
      "    last_unique, recursion_repeat = find_recursion(orig_etype, evalue, records)\n",
      "  File \"/Users/hiradekeishi/opt/anaconda3/envs/py3-TF2.0/lib/python3.7/site-packages/IPython/core/ultratb.py\", line 382, in find_recursion\n",
      "    return len(records), 0\n",
      "TypeError: object of type 'NoneType' has no len()\n",
      "\n",
      "During handling of the above exception, another exception occurred:\n",
      "\n",
      "Traceback (most recent call last):\n",
      "  File \"/Users/hiradekeishi/opt/anaconda3/envs/py3-TF2.0/lib/python3.7/site-packages/IPython/core/interactiveshell.py\", line 2077, in showtraceback\n",
      "    stb = value._render_traceback_()\n",
      "AttributeError: 'TypeError' object has no attribute '_render_traceback_'\n",
      "\n",
      "During handling of the above exception, another exception occurred:\n",
      "\n",
      "Traceback (most recent call last):\n",
      "  File \"/Users/hiradekeishi/opt/anaconda3/envs/py3-TF2.0/lib/python3.7/site-packages/IPython/core/ultratb.py\", line 1101, in get_records\n",
      "    return _fixed_getinnerframes(etb, number_of_lines_of_context, tb_offset)\n",
      "  File \"/Users/hiradekeishi/opt/anaconda3/envs/py3-TF2.0/lib/python3.7/site-packages/IPython/core/ultratb.py\", line 248, in wrapped\n",
      "    return f(*args, **kwargs)\n",
      "  File \"/Users/hiradekeishi/opt/anaconda3/envs/py3-TF2.0/lib/python3.7/site-packages/IPython/core/ultratb.py\", line 281, in _fixed_getinnerframes\n",
      "    records = fix_frame_records_filenames(inspect.getinnerframes(etb, context))\n",
      "  File \"/Users/hiradekeishi/opt/anaconda3/envs/py3-TF2.0/lib/python3.7/inspect.py\", line 1502, in getinnerframes\n",
      "    frameinfo = (tb.tb_frame,) + getframeinfo(tb, context)\n",
      "  File \"/Users/hiradekeishi/opt/anaconda3/envs/py3-TF2.0/lib/python3.7/inspect.py\", line 1460, in getframeinfo\n",
      "    filename = getsourcefile(frame) or getfile(frame)\n",
      "  File \"/Users/hiradekeishi/opt/anaconda3/envs/py3-TF2.0/lib/python3.7/inspect.py\", line 696, in getsourcefile\n",
      "    if getattr(getmodule(object, filename), '__loader__', None) is not None:\n",
      "  File \"/Users/hiradekeishi/opt/anaconda3/envs/py3-TF2.0/lib/python3.7/inspect.py\", line 733, in getmodule\n",
      "    if ismodule(module) and hasattr(module, '__file__'):\n",
      "  File \"/Users/hiradekeishi/opt/anaconda3/envs/py3-TF2.0/lib/python3.7/site-packages/tensorflow/__init__.py\", line 50, in __getattr__\n",
      "    module = self._load()\n",
      "  File \"/Users/hiradekeishi/opt/anaconda3/envs/py3-TF2.0/lib/python3.7/site-packages/tensorflow/__init__.py\", line 44, in _load\n",
      "    module = _importlib.import_module(self.__name__)\n",
      "  File \"/Users/hiradekeishi/opt/anaconda3/envs/py3-TF2.0/lib/python3.7/importlib/__init__.py\", line 127, in import_module\n",
      "    return _bootstrap._gcd_import(name[level:], package, level)\n",
      "  File \"<frozen importlib._bootstrap>\", line 1006, in _gcd_import\n",
      "  File \"<frozen importlib._bootstrap>\", line 983, in _find_and_load\n",
      "  File \"<frozen importlib._bootstrap>\", line 965, in _find_and_load_unlocked\n",
      "ModuleNotFoundError: No module named 'tensorflow_core.estimator'\n"
     ]
    }
   ],
   "source": [
    "mnist_dataset, mnist_info = tfds.load(name='mnist', with_info=True, as_supervised=True)\n",
    "\n",
    "\n"
   ]
  },
  {
   "cell_type": "code",
   "execution_count": null,
   "id": "620efc57",
   "metadata": {},
   "outputs": [],
   "source": []
  },
  {
   "cell_type": "code",
   "execution_count": null,
   "id": "20fd0c86",
   "metadata": {},
   "outputs": [],
   "source": []
  },
  {
   "cell_type": "code",
   "execution_count": null,
   "id": "02d82a0c",
   "metadata": {},
   "outputs": [],
   "source": []
  },
  {
   "cell_type": "code",
   "execution_count": null,
   "id": "c6416e53",
   "metadata": {},
   "outputs": [],
   "source": []
  },
  {
   "cell_type": "code",
   "execution_count": null,
   "id": "5751a328",
   "metadata": {},
   "outputs": [],
   "source": []
  }
 ],
 "metadata": {
  "kernelspec": {
   "display_name": "Python 3 (ipykernel)",
   "language": "python",
   "name": "python3"
  },
  "language_info": {
   "codemirror_mode": {
    "name": "ipython",
    "version": 3
   },
   "file_extension": ".py",
   "mimetype": "text/x-python",
   "name": "python",
   "nbconvert_exporter": "python",
   "pygments_lexer": "ipython3",
   "version": "3.7.11"
  }
 },
 "nbformat": 4,
 "nbformat_minor": 5
}
