{
 "cells": [
  {
   "cell_type": "code",
   "execution_count": 10,
   "id": "58e1110d",
   "metadata": {},
   "outputs": [
    {
     "name": "stdout",
     "output_type": "stream",
     "text": [
      "ERROR! Session/line number was not unique in database. History logging moved to new session 69\n"
     ]
    }
   ],
   "source": [
    "import numpy as np\n",
    "import tensorflow as tf\n",
    "import tensorflow_datasets as tfds"
   ]
  },
  {
   "cell_type": "code",
   "execution_count": null,
   "id": "a348fe21",
   "metadata": {},
   "outputs": [
    {
     "name": "stdout",
     "output_type": "stream",
     "text": [
      "ERROR! Session/line number was not unique in database. History logging moved to new session 68\n"
     ]
    },
    {
     "name": "stderr",
     "output_type": "stream",
     "text": [
      "ERROR:root:Internal Python error in the inspect module.\n",
      "Below is the traceback from this internal error.\n",
      "\n",
      "ERROR:root:Internal Python error in the inspect module.\n",
      "Below is the traceback from this internal error.\n",
      "\n",
      "ERROR:root:Internal Python error in the inspect module.\n",
      "Below is the traceback from this internal error.\n",
      "\n"
     ]
    },
    {
     "name": "stdout",
     "output_type": "stream",
     "text": [
      "\u001b[1mDownloading and preparing dataset mnist (11.06 MiB) to /Users/hiradekeishi/tensorflow_datasets/mnist/1.0.0...\u001b[0m\n",
      "Traceback (most recent call last):\n",
      "  File \"/Users/hiradekeishi/opt/anaconda3/envs/py3-TF2.0/lib/python3.7/site-packages/IPython/core/interactiveshell.py\", line 3457, in run_code\n",
      "    exec(code_obj, self.user_global_ns, self.user_ns)\n",
      "  File \"/var/folders/7_/5ly65s3j46zcgtgg9r0sjm940000gn/T/ipykernel_84481/993605201.py\", line 1, in <module>\n",
      "    mnist_dataset, mnist_info = tfds.load(name='mnist', with_info=True, as_supervised=True)\n",
      "  File \"/Users/hiradekeishi/Desktop/k-hirade_private/deep_learning/cakephp/Mnist/tensorflow_datasets/core/api_utils.py\", line 52, in disallow_positional_args_dec\n",
      "  File \"/Users/hiradekeishi/Desktop/k-hirade_private/deep_learning/cakephp/Mnist/tensorflow_datasets/core/registered.py\", line 300, in load\n",
      "  File \"/Users/hiradekeishi/Desktop/k-hirade_private/deep_learning/cakephp/Mnist/tensorflow_datasets/core/api_utils.py\", line 52, in disallow_positional_args_dec\n",
      "  File \"/Users/hiradekeishi/Desktop/k-hirade_private/deep_learning/cakephp/Mnist/tensorflow_datasets/core/dataset_builder.py\", line 287, in download_and_prepare\n",
      "  File \"/Users/hiradekeishi/Desktop/k-hirade_private/deep_learning/cakephp/Mnist/tensorflow_datasets/core/dataset_builder.py\", line 948, in _download_and_prepare\n",
      "  File \"/Users/hiradekeishi/Desktop/k-hirade_private/deep_learning/cakephp/Mnist/tensorflow_datasets/core/dataset_builder.py\", line 804, in _download_and_prepare\n",
      "  File \"/Users/hiradekeishi/Desktop/k-hirade_private/deep_learning/cakephp/Mnist/tensorflow_datasets/image/mnist.py\", line 132, in _split_generators\n",
      "  File \"/Users/hiradekeishi/Desktop/k-hirade_private/deep_learning/cakephp/Mnist/tensorflow_datasets/core/download/download_manager.py\", line 357, in download_and_extract\n",
      "  File \"/Users/hiradekeishi/opt/anaconda3/envs/py3-TF2.0/lib/python3.7/contextlib.py\", line 112, in __enter__\n",
      "    return next(self.gen)\n",
      "  File \"/Users/hiradekeishi/Desktop/k-hirade_private/deep_learning/cakephp/Mnist/tensorflow_datasets/core/download/downloader.py\", line 89, in tqdm\n",
      "  File \"/Users/hiradekeishi/opt/anaconda3/envs/py3-TF2.0/lib/python3.7/contextlib.py\", line 112, in __enter__\n",
      "    return next(self.gen)\n",
      "  File \"/Users/hiradekeishi/Desktop/k-hirade_private/deep_learning/cakephp/Mnist/tensorflow_datasets/core/utils/tqdm_utils.py\", line 98, in _async_tqdm\n",
      "  File \"/Users/hiradekeishi/opt/anaconda3/envs/py3-TF2.0/lib/python3.7/site-packages/tqdm/notebook.py\", line 242, in __init__\n",
      "    self.container = self.status_printer(self.fp, total, self.desc, self.ncols)\n",
      "  File \"/Users/hiradekeishi/opt/anaconda3/envs/py3-TF2.0/lib/python3.7/site-packages/tqdm/notebook.py\", line 116, in status_printer\n",
      "    \"IProgress not found. Please update jupyter and ipywidgets.\"\n",
      "ImportError: IProgress not found. Please update jupyter and ipywidgets. See https://ipywidgets.readthedocs.io/en/stable/user_install.html\n",
      "\n",
      "During handling of the above exception, another exception occurred:\n",
      "\n",
      "Traceback (most recent call last):\n",
      "  File \"/Users/hiradekeishi/opt/anaconda3/envs/py3-TF2.0/lib/python3.7/site-packages/IPython/core/interactiveshell.py\", line 2077, in showtraceback\n",
      "    stb = value._render_traceback_()\n",
      "AttributeError: 'ImportError' object has no attribute '_render_traceback_'\n",
      "\n",
      "During handling of the above exception, another exception occurred:\n",
      "\n",
      "Traceback (most recent call last):\n",
      "  File \"/Users/hiradekeishi/opt/anaconda3/envs/py3-TF2.0/lib/python3.7/site-packages/IPython/core/ultratb.py\", line 1101, in get_records\n",
      "    return _fixed_getinnerframes(etb, number_of_lines_of_context, tb_offset)\n",
      "  File \"/Users/hiradekeishi/opt/anaconda3/envs/py3-TF2.0/lib/python3.7/site-packages/IPython/core/ultratb.py\", line 248, in wrapped\n",
      "    return f(*args, **kwargs)\n",
      "  File \"/Users/hiradekeishi/opt/anaconda3/envs/py3-TF2.0/lib/python3.7/site-packages/IPython/core/ultratb.py\", line 281, in _fixed_getinnerframes\n",
      "    records = fix_frame_records_filenames(inspect.getinnerframes(etb, context))\n",
      "  File \"/Users/hiradekeishi/opt/anaconda3/envs/py3-TF2.0/lib/python3.7/inspect.py\", line 1502, in getinnerframes\n",
      "    frameinfo = (tb.tb_frame,) + getframeinfo(tb, context)\n",
      "  File \"/Users/hiradekeishi/opt/anaconda3/envs/py3-TF2.0/lib/python3.7/inspect.py\", line 1460, in getframeinfo\n",
      "    filename = getsourcefile(frame) or getfile(frame)\n",
      "  File \"/Users/hiradekeishi/opt/anaconda3/envs/py3-TF2.0/lib/python3.7/inspect.py\", line 696, in getsourcefile\n",
      "    if getattr(getmodule(object, filename), '__loader__', None) is not None:\n",
      "  File \"/Users/hiradekeishi/opt/anaconda3/envs/py3-TF2.0/lib/python3.7/inspect.py\", line 733, in getmodule\n",
      "    if ismodule(module) and hasattr(module, '__file__'):\n",
      "  File \"/Users/hiradekeishi/opt/anaconda3/envs/py3-TF2.0/lib/python3.7/site-packages/tensorflow/__init__.py\", line 50, in __getattr__\n",
      "    module = self._load()\n",
      "  File \"/Users/hiradekeishi/opt/anaconda3/envs/py3-TF2.0/lib/python3.7/site-packages/tensorflow/__init__.py\", line 44, in _load\n",
      "    module = _importlib.import_module(self.__name__)\n",
      "  File \"/Users/hiradekeishi/opt/anaconda3/envs/py3-TF2.0/lib/python3.7/importlib/__init__.py\", line 127, in import_module\n",
      "    return _bootstrap._gcd_import(name[level:], package, level)\n",
      "  File \"<frozen importlib._bootstrap>\", line 1006, in _gcd_import\n",
      "  File \"<frozen importlib._bootstrap>\", line 983, in _find_and_load\n",
      "  File \"<frozen importlib._bootstrap>\", line 965, in _find_and_load_unlocked\n",
      "ModuleNotFoundError: No module named 'tensorflow_core.estimator'\n",
      "Traceback (most recent call last):\n",
      "  File \"/Users/hiradekeishi/opt/anaconda3/envs/py3-TF2.0/lib/python3.7/site-packages/IPython/core/interactiveshell.py\", line 3457, in run_code\n",
      "    exec(code_obj, self.user_global_ns, self.user_ns)\n",
      "  File \"/var/folders/7_/5ly65s3j46zcgtgg9r0sjm940000gn/T/ipykernel_84481/993605201.py\", line 1, in <module>\n",
      "    mnist_dataset, mnist_info = tfds.load(name='mnist', with_info=True, as_supervised=True)\n",
      "  File \"/Users/hiradekeishi/Desktop/k-hirade_private/deep_learning/cakephp/Mnist/tensorflow_datasets/core/api_utils.py\", line 52, in disallow_positional_args_dec\n",
      "  File \"/Users/hiradekeishi/Desktop/k-hirade_private/deep_learning/cakephp/Mnist/tensorflow_datasets/core/registered.py\", line 300, in load\n",
      "  File \"/Users/hiradekeishi/Desktop/k-hirade_private/deep_learning/cakephp/Mnist/tensorflow_datasets/core/api_utils.py\", line 52, in disallow_positional_args_dec\n",
      "  File \"/Users/hiradekeishi/Desktop/k-hirade_private/deep_learning/cakephp/Mnist/tensorflow_datasets/core/dataset_builder.py\", line 287, in download_and_prepare\n",
      "  File \"/Users/hiradekeishi/Desktop/k-hirade_private/deep_learning/cakephp/Mnist/tensorflow_datasets/core/dataset_builder.py\", line 948, in _download_and_prepare\n",
      "  File \"/Users/hiradekeishi/Desktop/k-hirade_private/deep_learning/cakephp/Mnist/tensorflow_datasets/core/dataset_builder.py\", line 804, in _download_and_prepare\n",
      "  File \"/Users/hiradekeishi/Desktop/k-hirade_private/deep_learning/cakephp/Mnist/tensorflow_datasets/image/mnist.py\", line 132, in _split_generators\n",
      "  File \"/Users/hiradekeishi/Desktop/k-hirade_private/deep_learning/cakephp/Mnist/tensorflow_datasets/core/download/download_manager.py\", line 357, in download_and_extract\n",
      "  File \"/Users/hiradekeishi/opt/anaconda3/envs/py3-TF2.0/lib/python3.7/contextlib.py\", line 112, in __enter__\n",
      "    return next(self.gen)\n",
      "  File \"/Users/hiradekeishi/Desktop/k-hirade_private/deep_learning/cakephp/Mnist/tensorflow_datasets/core/download/downloader.py\", line 89, in tqdm\n",
      "  File \"/Users/hiradekeishi/opt/anaconda3/envs/py3-TF2.0/lib/python3.7/contextlib.py\", line 112, in __enter__\n",
      "    return next(self.gen)\n",
      "  File \"/Users/hiradekeishi/Desktop/k-hirade_private/deep_learning/cakephp/Mnist/tensorflow_datasets/core/utils/tqdm_utils.py\", line 98, in _async_tqdm\n",
      "  File \"/Users/hiradekeishi/opt/anaconda3/envs/py3-TF2.0/lib/python3.7/site-packages/tqdm/notebook.py\", line 242, in __init__\n",
      "    self.container = self.status_printer(self.fp, total, self.desc, self.ncols)\n",
      "  File \"/Users/hiradekeishi/opt/anaconda3/envs/py3-TF2.0/lib/python3.7/site-packages/tqdm/notebook.py\", line 116, in status_printer\n",
      "    \"IProgress not found. Please update jupyter and ipywidgets.\"\n",
      "ImportError: IProgress not found. Please update jupyter and ipywidgets. See https://ipywidgets.readthedocs.io/en/stable/user_install.html\n",
      "\n",
      "During handling of the above exception, another exception occurred:\n",
      "\n",
      "Traceback (most recent call last):\n",
      "  File \"/Users/hiradekeishi/opt/anaconda3/envs/py3-TF2.0/lib/python3.7/site-packages/IPython/core/interactiveshell.py\", line 2077, in showtraceback\n",
      "    stb = value._render_traceback_()\n",
      "AttributeError: 'ImportError' object has no attribute '_render_traceback_'\n",
      "\n",
      "During handling of the above exception, another exception occurred:\n",
      "\n",
      "Traceback (most recent call last):\n",
      "  File \"/Users/hiradekeishi/opt/anaconda3/envs/py3-TF2.0/lib/python3.7/site-packages/IPython/core/interactiveshell.py\", line 3377, in run_ast_nodes\n",
      "    if (await self.run_code(code, result,  async_=asy)):\n",
      "  File \"/Users/hiradekeishi/opt/anaconda3/envs/py3-TF2.0/lib/python3.7/site-packages/IPython/core/interactiveshell.py\", line 3474, in run_code\n",
      "    self.showtraceback(running_compiled_code=True)\n",
      "  File \"/Users/hiradekeishi/opt/anaconda3/envs/py3-TF2.0/lib/python3.7/site-packages/IPython/core/interactiveshell.py\", line 2080, in showtraceback\n",
      "    value, tb, tb_offset=tb_offset)\n",
      "  File \"/Users/hiradekeishi/opt/anaconda3/envs/py3-TF2.0/lib/python3.7/site-packages/IPython/core/ultratb.py\", line 1368, in structured_traceback\n",
      "    self, etype, value, tb, tb_offset, number_of_lines_of_context)\n",
      "  File \"/Users/hiradekeishi/opt/anaconda3/envs/py3-TF2.0/lib/python3.7/site-packages/IPython/core/ultratb.py\", line 1268, in structured_traceback\n",
      "    self, etype, value, tb, tb_offset, number_of_lines_of_context\n",
      "  File \"/Users/hiradekeishi/opt/anaconda3/envs/py3-TF2.0/lib/python3.7/site-packages/IPython/core/ultratb.py\", line 1125, in structured_traceback\n",
      "    tb_offset)\n",
      "  File \"/Users/hiradekeishi/opt/anaconda3/envs/py3-TF2.0/lib/python3.7/site-packages/IPython/core/ultratb.py\", line 1082, in format_exception_as_a_whole\n",
      "    last_unique, recursion_repeat = find_recursion(orig_etype, evalue, records)\n",
      "  File \"/Users/hiradekeishi/opt/anaconda3/envs/py3-TF2.0/lib/python3.7/site-packages/IPython/core/ultratb.py\", line 382, in find_recursion\n",
      "    return len(records), 0\n",
      "TypeError: object of type 'NoneType' has no len()\n",
      "\n",
      "During handling of the above exception, another exception occurred:\n",
      "\n",
      "Traceback (most recent call last):\n",
      "  File \"/Users/hiradekeishi/opt/anaconda3/envs/py3-TF2.0/lib/python3.7/site-packages/IPython/core/interactiveshell.py\", line 2077, in showtraceback\n",
      "    stb = value._render_traceback_()\n",
      "AttributeError: 'TypeError' object has no attribute '_render_traceback_'\n",
      "\n",
      "During handling of the above exception, another exception occurred:\n",
      "\n",
      "Traceback (most recent call last):\n",
      "  File \"/Users/hiradekeishi/opt/anaconda3/envs/py3-TF2.0/lib/python3.7/site-packages/IPython/core/ultratb.py\", line 1101, in get_records\n",
      "    return _fixed_getinnerframes(etb, number_of_lines_of_context, tb_offset)\n",
      "  File \"/Users/hiradekeishi/opt/anaconda3/envs/py3-TF2.0/lib/python3.7/site-packages/IPython/core/ultratb.py\", line 248, in wrapped\n",
      "    return f(*args, **kwargs)\n",
      "  File \"/Users/hiradekeishi/opt/anaconda3/envs/py3-TF2.0/lib/python3.7/site-packages/IPython/core/ultratb.py\", line 281, in _fixed_getinnerframes\n",
      "    records = fix_frame_records_filenames(inspect.getinnerframes(etb, context))\n",
      "  File \"/Users/hiradekeishi/opt/anaconda3/envs/py3-TF2.0/lib/python3.7/inspect.py\", line 1502, in getinnerframes\n",
      "    frameinfo = (tb.tb_frame,) + getframeinfo(tb, context)\n",
      "  File \"/Users/hiradekeishi/opt/anaconda3/envs/py3-TF2.0/lib/python3.7/inspect.py\", line 1460, in getframeinfo\n",
      "    filename = getsourcefile(frame) or getfile(frame)\n",
      "  File \"/Users/hiradekeishi/opt/anaconda3/envs/py3-TF2.0/lib/python3.7/inspect.py\", line 696, in getsourcefile\n",
      "    if getattr(getmodule(object, filename), '__loader__', None) is not None:\n",
      "  File \"/Users/hiradekeishi/opt/anaconda3/envs/py3-TF2.0/lib/python3.7/inspect.py\", line 733, in getmodule\n",
      "    if ismodule(module) and hasattr(module, '__file__'):\n",
      "  File \"/Users/hiradekeishi/opt/anaconda3/envs/py3-TF2.0/lib/python3.7/site-packages/tensorflow/__init__.py\", line 50, in __getattr__\n",
      "    module = self._load()\n",
      "  File \"/Users/hiradekeishi/opt/anaconda3/envs/py3-TF2.0/lib/python3.7/site-packages/tensorflow/__init__.py\", line 44, in _load\n",
      "    module = _importlib.import_module(self.__name__)\n",
      "  File \"/Users/hiradekeishi/opt/anaconda3/envs/py3-TF2.0/lib/python3.7/importlib/__init__.py\", line 127, in import_module\n",
      "    return _bootstrap._gcd_import(name[level:], package, level)\n",
      "  File \"<frozen importlib._bootstrap>\", line 1006, in _gcd_import\n",
      "  File \"<frozen importlib._bootstrap>\", line 983, in _find_and_load\n",
      "  File \"<frozen importlib._bootstrap>\", line 965, in _find_and_load_unlocked\n",
      "ModuleNotFoundError: No module named 'tensorflow_core.estimator'\n",
      "Traceback (most recent call last):\n",
      "  File \"/Users/hiradekeishi/opt/anaconda3/envs/py3-TF2.0/lib/python3.7/site-packages/IPython/core/interactiveshell.py\", line 3457, in run_code\n",
      "    exec(code_obj, self.user_global_ns, self.user_ns)\n",
      "  File \"/var/folders/7_/5ly65s3j46zcgtgg9r0sjm940000gn/T/ipykernel_84481/993605201.py\", line 1, in <module>\n",
      "    mnist_dataset, mnist_info = tfds.load(name='mnist', with_info=True, as_supervised=True)\n",
      "  File \"/Users/hiradekeishi/Desktop/k-hirade_private/deep_learning/cakephp/Mnist/tensorflow_datasets/core/api_utils.py\", line 52, in disallow_positional_args_dec\n",
      "  File \"/Users/hiradekeishi/Desktop/k-hirade_private/deep_learning/cakephp/Mnist/tensorflow_datasets/core/registered.py\", line 300, in load\n",
      "  File \"/Users/hiradekeishi/Desktop/k-hirade_private/deep_learning/cakephp/Mnist/tensorflow_datasets/core/api_utils.py\", line 52, in disallow_positional_args_dec\n",
      "  File \"/Users/hiradekeishi/Desktop/k-hirade_private/deep_learning/cakephp/Mnist/tensorflow_datasets/core/dataset_builder.py\", line 287, in download_and_prepare\n",
      "  File \"/Users/hiradekeishi/Desktop/k-hirade_private/deep_learning/cakephp/Mnist/tensorflow_datasets/core/dataset_builder.py\", line 948, in _download_and_prepare\n",
      "  File \"/Users/hiradekeishi/Desktop/k-hirade_private/deep_learning/cakephp/Mnist/tensorflow_datasets/core/dataset_builder.py\", line 804, in _download_and_prepare\n",
      "  File \"/Users/hiradekeishi/Desktop/k-hirade_private/deep_learning/cakephp/Mnist/tensorflow_datasets/image/mnist.py\", line 132, in _split_generators\n",
      "  File \"/Users/hiradekeishi/Desktop/k-hirade_private/deep_learning/cakephp/Mnist/tensorflow_datasets/core/download/download_manager.py\", line 357, in download_and_extract\n",
      "  File \"/Users/hiradekeishi/opt/anaconda3/envs/py3-TF2.0/lib/python3.7/contextlib.py\", line 112, in __enter__\n",
      "    return next(self.gen)\n",
      "  File \"/Users/hiradekeishi/Desktop/k-hirade_private/deep_learning/cakephp/Mnist/tensorflow_datasets/core/download/downloader.py\", line 89, in tqdm\n",
      "  File \"/Users/hiradekeishi/opt/anaconda3/envs/py3-TF2.0/lib/python3.7/contextlib.py\", line 112, in __enter__\n",
      "    return next(self.gen)\n",
      "  File \"/Users/hiradekeishi/Desktop/k-hirade_private/deep_learning/cakephp/Mnist/tensorflow_datasets/core/utils/tqdm_utils.py\", line 98, in _async_tqdm\n",
      "  File \"/Users/hiradekeishi/opt/anaconda3/envs/py3-TF2.0/lib/python3.7/site-packages/tqdm/notebook.py\", line 242, in __init__\n",
      "    self.container = self.status_printer(self.fp, total, self.desc, self.ncols)\n",
      "  File \"/Users/hiradekeishi/opt/anaconda3/envs/py3-TF2.0/lib/python3.7/site-packages/tqdm/notebook.py\", line 116, in status_printer\n",
      "    \"IProgress not found. Please update jupyter and ipywidgets.\"\n",
      "ImportError: IProgress not found. Please update jupyter and ipywidgets. See https://ipywidgets.readthedocs.io/en/stable/user_install.html\n",
      "\n",
      "During handling of the above exception, another exception occurred:\n",
      "\n",
      "Traceback (most recent call last):\n",
      "  File \"/Users/hiradekeishi/opt/anaconda3/envs/py3-TF2.0/lib/python3.7/site-packages/IPython/core/interactiveshell.py\", line 2077, in showtraceback\n",
      "    stb = value._render_traceback_()\n",
      "AttributeError: 'ImportError' object has no attribute '_render_traceback_'\n",
      "\n",
      "During handling of the above exception, another exception occurred:\n",
      "\n",
      "Traceback (most recent call last):\n",
      "  File \"/Users/hiradekeishi/opt/anaconda3/envs/py3-TF2.0/lib/python3.7/site-packages/IPython/core/interactiveshell.py\", line 3377, in run_ast_nodes\n",
      "    if (await self.run_code(code, result,  async_=asy)):\n",
      "  File \"/Users/hiradekeishi/opt/anaconda3/envs/py3-TF2.0/lib/python3.7/site-packages/IPython/core/interactiveshell.py\", line 3474, in run_code\n",
      "    self.showtraceback(running_compiled_code=True)\n",
      "  File \"/Users/hiradekeishi/opt/anaconda3/envs/py3-TF2.0/lib/python3.7/site-packages/IPython/core/interactiveshell.py\", line 2080, in showtraceback\n",
      "    value, tb, tb_offset=tb_offset)\n",
      "  File \"/Users/hiradekeishi/opt/anaconda3/envs/py3-TF2.0/lib/python3.7/site-packages/IPython/core/ultratb.py\", line 1368, in structured_traceback\n",
      "    self, etype, value, tb, tb_offset, number_of_lines_of_context)\n",
      "  File \"/Users/hiradekeishi/opt/anaconda3/envs/py3-TF2.0/lib/python3.7/site-packages/IPython/core/ultratb.py\", line 1268, in structured_traceback\n",
      "    self, etype, value, tb, tb_offset, number_of_lines_of_context\n",
      "  File \"/Users/hiradekeishi/opt/anaconda3/envs/py3-TF2.0/lib/python3.7/site-packages/IPython/core/ultratb.py\", line 1125, in structured_traceback\n",
      "    tb_offset)\n",
      "  File \"/Users/hiradekeishi/opt/anaconda3/envs/py3-TF2.0/lib/python3.7/site-packages/IPython/core/ultratb.py\", line 1082, in format_exception_as_a_whole\n",
      "    last_unique, recursion_repeat = find_recursion(orig_etype, evalue, records)\n",
      "  File \"/Users/hiradekeishi/opt/anaconda3/envs/py3-TF2.0/lib/python3.7/site-packages/IPython/core/ultratb.py\", line 382, in find_recursion\n",
      "    return len(records), 0\n",
      "TypeError: object of type 'NoneType' has no len()\n",
      "\n",
      "During handling of the above exception, another exception occurred:\n",
      "\n",
      "Traceback (most recent call last):\n",
      "  File \"/Users/hiradekeishi/opt/anaconda3/envs/py3-TF2.0/lib/python3.7/site-packages/IPython/core/interactiveshell.py\", line 2077, in showtraceback\n",
      "    stb = value._render_traceback_()\n",
      "AttributeError: 'TypeError' object has no attribute '_render_traceback_'\n",
      "\n",
      "During handling of the above exception, another exception occurred:\n",
      "\n",
      "Traceback (most recent call last):\n",
      "  File \"/Users/hiradekeishi/opt/anaconda3/envs/py3-TF2.0/lib/python3.7/site-packages/IPython/core/interactiveshell.py\", line 2960, in _run_cell\n",
      "    return runner(coro)\n",
      "  File \"/Users/hiradekeishi/opt/anaconda3/envs/py3-TF2.0/lib/python3.7/site-packages/IPython/core/async_helpers.py\", line 78, in _pseudo_sync_runner\n",
      "    coro.send(None)\n",
      "  File \"/Users/hiradekeishi/opt/anaconda3/envs/py3-TF2.0/lib/python3.7/site-packages/IPython/core/interactiveshell.py\", line 3186, in run_cell_async\n",
      "    interactivity=interactivity, compiler=compiler, result=result)\n",
      "  File \"/Users/hiradekeishi/opt/anaconda3/envs/py3-TF2.0/lib/python3.7/site-packages/IPython/core/interactiveshell.py\", line 3396, in run_ast_nodes\n",
      "    self.showtraceback()\n",
      "  File \"/Users/hiradekeishi/opt/anaconda3/envs/py3-TF2.0/lib/python3.7/site-packages/IPython/core/interactiveshell.py\", line 2080, in showtraceback\n",
      "    value, tb, tb_offset=tb_offset)\n",
      "  File \"/Users/hiradekeishi/opt/anaconda3/envs/py3-TF2.0/lib/python3.7/site-packages/IPython/core/ultratb.py\", line 1368, in structured_traceback\n",
      "    self, etype, value, tb, tb_offset, number_of_lines_of_context)\n",
      "  File \"/Users/hiradekeishi/opt/anaconda3/envs/py3-TF2.0/lib/python3.7/site-packages/IPython/core/ultratb.py\", line 1268, in structured_traceback\n",
      "    self, etype, value, tb, tb_offset, number_of_lines_of_context\n",
      "  File \"/Users/hiradekeishi/opt/anaconda3/envs/py3-TF2.0/lib/python3.7/site-packages/IPython/core/ultratb.py\", line 1143, in structured_traceback\n",
      "    chained_exceptions_tb_offset)\n",
      "  File \"/Users/hiradekeishi/opt/anaconda3/envs/py3-TF2.0/lib/python3.7/site-packages/IPython/core/ultratb.py\", line 1082, in format_exception_as_a_whole\n",
      "    last_unique, recursion_repeat = find_recursion(orig_etype, evalue, records)\n",
      "  File \"/Users/hiradekeishi/opt/anaconda3/envs/py3-TF2.0/lib/python3.7/site-packages/IPython/core/ultratb.py\", line 382, in find_recursion\n",
      "    return len(records), 0\n",
      "TypeError: object of type 'NoneType' has no len()\n",
      "\n",
      "During handling of the above exception, another exception occurred:\n",
      "\n",
      "Traceback (most recent call last):\n",
      "  File \"/Users/hiradekeishi/opt/anaconda3/envs/py3-TF2.0/lib/python3.7/site-packages/IPython/core/interactiveshell.py\", line 2077, in showtraceback\n",
      "    stb = value._render_traceback_()\n",
      "AttributeError: 'TypeError' object has no attribute '_render_traceback_'\n",
      "\n",
      "During handling of the above exception, another exception occurred:\n",
      "\n",
      "Traceback (most recent call last):\n",
      "  File \"/Users/hiradekeishi/opt/anaconda3/envs/py3-TF2.0/lib/python3.7/site-packages/IPython/core/ultratb.py\", line 1101, in get_records\n",
      "    return _fixed_getinnerframes(etb, number_of_lines_of_context, tb_offset)\n",
      "  File \"/Users/hiradekeishi/opt/anaconda3/envs/py3-TF2.0/lib/python3.7/site-packages/IPython/core/ultratb.py\", line 248, in wrapped\n",
      "    return f(*args, **kwargs)\n",
      "  File \"/Users/hiradekeishi/opt/anaconda3/envs/py3-TF2.0/lib/python3.7/site-packages/IPython/core/ultratb.py\", line 281, in _fixed_getinnerframes\n",
      "    records = fix_frame_records_filenames(inspect.getinnerframes(etb, context))\n",
      "  File \"/Users/hiradekeishi/opt/anaconda3/envs/py3-TF2.0/lib/python3.7/inspect.py\", line 1502, in getinnerframes\n",
      "    frameinfo = (tb.tb_frame,) + getframeinfo(tb, context)\n",
      "  File \"/Users/hiradekeishi/opt/anaconda3/envs/py3-TF2.0/lib/python3.7/inspect.py\", line 1460, in getframeinfo\n",
      "    filename = getsourcefile(frame) or getfile(frame)\n",
      "  File \"/Users/hiradekeishi/opt/anaconda3/envs/py3-TF2.0/lib/python3.7/inspect.py\", line 696, in getsourcefile\n",
      "    if getattr(getmodule(object, filename), '__loader__', None) is not None:\n",
      "  File \"/Users/hiradekeishi/opt/anaconda3/envs/py3-TF2.0/lib/python3.7/inspect.py\", line 733, in getmodule\n",
      "    if ismodule(module) and hasattr(module, '__file__'):\n",
      "  File \"/Users/hiradekeishi/opt/anaconda3/envs/py3-TF2.0/lib/python3.7/site-packages/tensorflow/__init__.py\", line 50, in __getattr__\n",
      "    module = self._load()\n",
      "  File \"/Users/hiradekeishi/opt/anaconda3/envs/py3-TF2.0/lib/python3.7/site-packages/tensorflow/__init__.py\", line 44, in _load\n",
      "    module = _importlib.import_module(self.__name__)\n",
      "  File \"/Users/hiradekeishi/opt/anaconda3/envs/py3-TF2.0/lib/python3.7/importlib/__init__.py\", line 127, in import_module\n",
      "    return _bootstrap._gcd_import(name[level:], package, level)\n",
      "  File \"<frozen importlib._bootstrap>\", line 1006, in _gcd_import\n",
      "  File \"<frozen importlib._bootstrap>\", line 983, in _find_and_load\n",
      "  File \"<frozen importlib._bootstrap>\", line 965, in _find_and_load_unlocked\n",
      "ModuleNotFoundError: No module named 'tensorflow_core.estimator'\n"
     ]
    }
   ],
   "source": [
    "mnist_dataset, mnist_info = tfds.load(name='mnist', with_info=True, as_supervised=True)\n",
    "# with_info=True をすることによって、データに関する情報を得ることができるようになる\n",
    "# as_supervised=Trueをすることによって、データを入力とターゲットの二つののタプル形式で作成する\n",
    "\n",
    "print(mnist_info)\n",
    "\n",
    "mnist_train, mnist_test = mnist_dataset['train'], mnist_dataset['test']\n",
    "\n",
    "# info.splits['train'].num_examplesでデータを格納、検証データ\n",
    "num_validation_samples = 0.1 * mnist_info.splits['train'].num_examples\n",
    "# 数字を整数に変換\n",
    "num_validation_samples = tf.cast(num_validation_samples, tf.int64)\n",
    "\n",
    "# テストデータの数も変数に入力\n",
    "num_test_samples = mnist_info.splits['test'].num_examples\n",
    "# 数字を整数に変換\n",
    "num_test_samples = tf.cast(num_test_samples, tf.int64)\n",
    "\n",
    "# 元の入力データの範囲である0から255を0と1に変換\n",
    "# 変換するための関数を作成\n",
    "def scale(image, label):\n",
    "    # 数字が小数であることを確認\n",
    "    image = tf.cast(image, tf.float32)\n",
    "    # 0と1の範囲におさめるため、255で割る\n",
    "    image /= 255.\n",
    "    return image, label\n",
    "\n",
    "# mapメソッドでデータの変換(リストの要素に関数・処理を適用)\n",
    "scaled_train_and_validation_data = mnist_train.map(scale)\n",
    "test_data = mnist_test.map(scale)\n",
    "\n",
    "\n",
    "#データをシャッフルするためのバッファのサイズを決定\n",
    "# 一時的にデータを先読みさせておくデータを貯めておくことをバッファ。\n",
    "# この大きさのことをバッファサイズという\n",
    "BUFFER_SIZE = 10000\n",
    "\n",
    "# シャッフルメソッドを使ってデータをシャッフル\n",
    "shuffled_train_and_validation_data = scaled_train_and_validation_data.shuffle(BUFFER_SIZE)\n",
    "\n",
    "# takeメソッドを使ってシャッフルした検証用データを変数に代入\n",
    "validation_data = shuffled_train_and_validation_data.take(num_validation_samples)\n",
    "\n",
    "# skipメソッドを使って訓練用データセットを変数に代入\n",
    "train_data = shuffled_train_and_validation_data.skip(num_validation_samples)\n",
    "\n",
    "# batchの大きさを定義\n",
    "BATCH_SIZE = 100\n",
    "\n",
    "# 訓練データをバッチの数毎に分割\n",
    "train_data = train_data.batch(BATCH_SIZE)\n",
    "\n",
    "validation_data = validation_data.batch(num_validation_samples)\n",
    "\n",
    "# テストデータに関してもバッチ毎に分割\n",
    "test_data = test_data.batch(num_test_samples)\n",
    "\n",
    "\n",
    "# バリデーションデータセットに関し、入力とターゲットそれぞれの変数を作成\n",
    "validation_inputs, validation_targets = next(iter(validation_data))"
   ]
  },
  {
   "cell_type": "code",
   "execution_count": 11,
   "id": "620efc57",
   "metadata": {},
   "outputs": [
    {
     "name": "stderr",
     "output_type": "stream",
     "text": [
      "Exception ignored in: <function tqdm.__del__ at 0x7f8e3cfc9a70>\n",
      "Traceback (most recent call last):\n",
      "  File \"/Users/hiradekeishi/opt/anaconda3/envs/py3-TF2.0/lib/python3.7/site-packages/tqdm/std.py\", line 1147, in __del__\n",
      "    self.close()\n",
      "  File \"/Users/hiradekeishi/opt/anaconda3/envs/py3-TF2.0/lib/python3.7/site-packages/tqdm/notebook.py\", line 289, in close\n",
      "    self.disp(bar_style='success', check_delay=False)\n",
      "AttributeError: 'tqdm' object has no attribute 'disp'\n",
      "Exception ignored in: <function tqdm.__del__ at 0x7f8e3cfc9a70>\n",
      "Traceback (most recent call last):\n",
      "  File \"/Users/hiradekeishi/opt/anaconda3/envs/py3-TF2.0/lib/python3.7/site-packages/tqdm/std.py\", line 1147, in __del__\n",
      "    self.close()\n",
      "  File \"/Users/hiradekeishi/opt/anaconda3/envs/py3-TF2.0/lib/python3.7/site-packages/tqdm/notebook.py\", line 289, in close\n",
      "    self.disp(bar_style='success', check_delay=False)\n",
      "AttributeError: 'tqdm' object has no attribute 'disp'\n",
      "Exception ignored in: <function tqdm.__del__ at 0x7f8e3cfc9a70>\n",
      "Traceback (most recent call last):\n",
      "  File \"/Users/hiradekeishi/opt/anaconda3/envs/py3-TF2.0/lib/python3.7/site-packages/tqdm/std.py\", line 1147, in __del__\n",
      "    self.close()\n",
      "  File \"/Users/hiradekeishi/opt/anaconda3/envs/py3-TF2.0/lib/python3.7/site-packages/tqdm/notebook.py\", line 289, in close\n",
      "    self.disp(bar_style='success', check_delay=False)\n",
      "AttributeError: 'tqdm' object has no attribute 'disp'\n",
      "Exception ignored in: <function tqdm.__del__ at 0x7f8e3cfc9a70>\n",
      "Traceback (most recent call last):\n",
      "  File \"/Users/hiradekeishi/opt/anaconda3/envs/py3-TF2.0/lib/python3.7/site-packages/tqdm/std.py\", line 1147, in __del__\n",
      "    self.close()\n",
      "  File \"/Users/hiradekeishi/opt/anaconda3/envs/py3-TF2.0/lib/python3.7/site-packages/tqdm/notebook.py\", line 289, in close\n",
      "    self.disp(bar_style='success', check_delay=False)\n",
      "AttributeError: 'tqdm' object has no attribute 'disp'\n",
      "Exception ignored in: <function tqdm.__del__ at 0x7f8e3cfc9a70>\n",
      "Traceback (most recent call last):\n",
      "  File \"/Users/hiradekeishi/opt/anaconda3/envs/py3-TF2.0/lib/python3.7/site-packages/tqdm/std.py\", line 1147, in __del__\n",
      "    self.close()\n",
      "  File \"/Users/hiradekeishi/opt/anaconda3/envs/py3-TF2.0/lib/python3.7/site-packages/tqdm/notebook.py\", line 289, in close\n",
      "    self.disp(bar_style='success', check_delay=False)\n",
      "AttributeError: 'tqdm' object has no attribute 'disp'\n",
      "Exception ignored in: <function tqdm.__del__ at 0x7f8e3cfc9a70>\n",
      "Traceback (most recent call last):\n",
      "  File \"/Users/hiradekeishi/opt/anaconda3/envs/py3-TF2.0/lib/python3.7/site-packages/tqdm/std.py\", line 1147, in __del__\n",
      "    self.close()\n",
      "  File \"/Users/hiradekeishi/opt/anaconda3/envs/py3-TF2.0/lib/python3.7/site-packages/tqdm/notebook.py\", line 289, in close\n",
      "    self.disp(bar_style='success', check_delay=False)\n",
      "AttributeError: 'tqdm' object has no attribute 'disp'\n",
      "Exception ignored in: <function tqdm.__del__ at 0x7f8e3cfc9a70>\n",
      "Traceback (most recent call last):\n",
      "  File \"/Users/hiradekeishi/opt/anaconda3/envs/py3-TF2.0/lib/python3.7/site-packages/tqdm/std.py\", line 1147, in __del__\n",
      "    self.close()\n",
      "  File \"/Users/hiradekeishi/opt/anaconda3/envs/py3-TF2.0/lib/python3.7/site-packages/tqdm/notebook.py\", line 289, in close\n",
      "    self.disp(bar_style='success', check_delay=False)\n",
      "AttributeError: 'tqdm' object has no attribute 'disp'\n",
      "Exception ignored in: <function tqdm.__del__ at 0x7f8e3cfc9a70>\n",
      "Traceback (most recent call last):\n",
      "  File \"/Users/hiradekeishi/opt/anaconda3/envs/py3-TF2.0/lib/python3.7/site-packages/tqdm/std.py\", line 1147, in __del__\n",
      "    self.close()\n",
      "  File \"/Users/hiradekeishi/opt/anaconda3/envs/py3-TF2.0/lib/python3.7/site-packages/tqdm/notebook.py\", line 289, in close\n",
      "    self.disp(bar_style='success', check_delay=False)\n",
      "AttributeError: 'tqdm' object has no attribute 'disp'\n",
      "2022-03-13 20:37:50.594768: I tensorflow/core/platform/cpu_feature_guard.cc:145] This TensorFlow binary is optimized with Intel(R) MKL-DNN to use the following CPU instructions in performance critical operations:  SSE4.1 SSE4.2\n",
      "To enable them in non-MKL-DNN operations, rebuild TensorFlow with the appropriate compiler flags.\n",
      "2022-03-13 20:37:50.596628: I tensorflow/core/common_runtime/process_util.cc:115] Creating new thread pool with default inter op setting: 8. Tune using inter_op_parallelism_threads for best performance.\n"
     ]
    }
   ],
   "source": [
    "input_size = 784\n",
    "output_size = 10\n",
    "# 隠れ層のユニットの数を定義\n",
    "hidden_layer_size = 50\n",
    "    \n",
    "# モデルの定義\n",
    "model = tf.keras.Sequential([\n",
    "    \n",
    "    # 入力層の定義\n",
    "    # もとの行列のデータをベクトルに変換\n",
    "    tf.keras.layers.Flatten(input_shape=(28, 28, 1)), # 入力層\n",
    "    \n",
    "    # tf.keras.layers.Dense は線形結合をするための計算->入力と重みの積にバイアスを追加する\n",
    "    # 引数として、ここでは隠れ層の数と活性化関数を指定\n",
    "    tf.keras.layers.Dense(hidden_layer_size, activation='relu'), # 1番目の隠れ層\n",
    "    tf.keras.layers.Dense(hidden_layer_size, activation='relu'), # 2番目の隠れ層\n",
    "    \n",
    "    # 最後の層の活性関数はソフトマックス\n",
    "    tf.keras.layers.Dense(output_size, activation='softmax') # 出力層\n",
    "])"
   ]
  },
  {
   "cell_type": "code",
   "execution_count": null,
   "id": "2d644efb",
   "metadata": {},
   "outputs": [],
   "source": []
  },
  {
   "cell_type": "code",
   "execution_count": null,
   "id": "80544cce",
   "metadata": {},
   "outputs": [],
   "source": []
  },
  {
   "cell_type": "code",
   "execution_count": null,
   "id": "2d1c75ae",
   "metadata": {},
   "outputs": [],
   "source": []
  },
  {
   "cell_type": "code",
   "execution_count": null,
   "id": "d095a914",
   "metadata": {},
   "outputs": [],
   "source": []
  },
  {
   "cell_type": "code",
   "execution_count": null,
   "id": "88e03289",
   "metadata": {},
   "outputs": [],
   "source": []
  },
  {
   "cell_type": "code",
   "execution_count": null,
   "id": "67ff9fd1",
   "metadata": {},
   "outputs": [],
   "source": []
  },
  {
   "cell_type": "code",
   "execution_count": null,
   "id": "f01a4cee",
   "metadata": {},
   "outputs": [],
   "source": []
  },
  {
   "cell_type": "code",
   "execution_count": null,
   "id": "60c5a9a8",
   "metadata": {},
   "outputs": [],
   "source": []
  },
  {
   "cell_type": "code",
   "execution_count": null,
   "id": "a8108969",
   "metadata": {},
   "outputs": [],
   "source": []
  },
  {
   "cell_type": "code",
   "execution_count": null,
   "id": "424db6fa",
   "metadata": {},
   "outputs": [],
   "source": []
  },
  {
   "cell_type": "code",
   "execution_count": null,
   "id": "328a0d2e",
   "metadata": {},
   "outputs": [],
   "source": []
  },
  {
   "cell_type": "code",
   "execution_count": null,
   "id": "20fd0c86",
   "metadata": {},
   "outputs": [],
   "source": []
  },
  {
   "cell_type": "code",
   "execution_count": null,
   "id": "02d82a0c",
   "metadata": {},
   "outputs": [],
   "source": []
  },
  {
   "cell_type": "code",
   "execution_count": null,
   "id": "c6416e53",
   "metadata": {},
   "outputs": [],
   "source": []
  },
  {
   "cell_type": "code",
   "execution_count": null,
   "id": "5751a328",
   "metadata": {},
   "outputs": [],
   "source": []
  }
 ],
 "metadata": {
  "kernelspec": {
   "display_name": "Python 3 (ipykernel)",
   "language": "python",
   "name": "python3"
  },
  "language_info": {
   "codemirror_mode": {
    "name": "ipython",
    "version": 3
   },
   "file_extension": ".py",
   "mimetype": "text/x-python",
   "name": "python",
   "nbconvert_exporter": "python",
   "pygments_lexer": "ipython3",
   "version": "3.7.11"
  }
 },
 "nbformat": 4,
 "nbformat_minor": 5
}
